<?xml version="1.0"?>

<robot name="example">
  
  <!-- *************************************************** -->
  <!-- ***************** Kinematic Chain ***************** -->
  <!-- *************************************************** -->
  <!-- Note the 'origin' tag in the joints defines the
       shift and reorientation before the continuous joint
       rotates around the 'axis'. -->

  <!-- Locate the base plate at the world origin. -->
  <joint name="place" type="fixed">
    <parent link="world"/>
    <child  link="baseplate"/>
    <origin xyz="0 0 0" rpy="0 0 0"/>
  </joint>

  <!-- Shift across the base plate to the base motor. -->
  <joint name="baseplate" type="fixed">
    <parent link="baseplate"/>
    <child  link="basemotor"/>
    <origin xyz="0 0 0.02" rpy="0 0 0"/>
  </joint>

  <!-- Base motor.  Thickness: X5 = 31.1mm, X8 = 45.1mm -->
  <joint name="base" type="continuous">
    <parent link="basemotor"/>
    <child  link="lbracket"/>
    <origin xyz="0 0 0.0311" rpy="0 0 0"/>
    <axis   xyz="0 0 1"/>
  </joint>

  <!-- Shift across the L bracket -->
  <joint name="lbracket" type="fixed">
    <parent link="lbracket"/>
    <child  link="shouldermotor"/>
    <origin xyz="0.1 0 0.1" rpy="1.5708 0 -1.5708"/>
  </joint>

  <!-- Shoulder motor.  Thickness: X5 = 31.1mm, X8 = 45.1mm -->
  <joint name="shoulder" type="continuous">
    <parent link="shouldermotor"/>
    <child  link="upperarm"/>
    <origin xyz="0 0 0.0451" rpy="0 0 0"/>
    <axis   xyz="0 0 1"/>
  </joint>

  <!-- Shift across the upper arm (1/4in thickness) -->
  <joint name="upperarm" type="fixed">
    <parent link="upperarm"/>
    <child  link="elbowmotor"/>
    <origin xyz="0.5 0 0.00635" rpy="0 0 0"/>
  </joint>

  <!-- Elbow motor.  Thickness: X5 = 31.1mm, X8 = 45.1mm -->
  <joint name="elbow" type="continuous">
    <parent link="elbowmotor"/>
    <child  link="lowerarm"/>
    <origin xyz="0 0 0.0311" rpy="0 0 0"/>
    <axis   xyz="0 0 1"/>
  </joint>

  <!-- Shift across the upper arm (1/4in thickness) -->
  <joint name="lowerarm" type="fixed">
    <parent link="lowerarm"/>
    <child  link="tip"/>
    <origin xyz="0.5 0 0.003175" rpy="0 0 0"/>
  </joint>

  
  <!-- *************************************************** -->
  <!-- *************** Visual Link Elements ************** -->
  <!-- *************************************************** -->
  <!-- Note collada .dae files have better color/texture   -->
  <!-- suppport that STL files.                            -->

  <!-- Colors -->
  <material name="wood">  <color rgba="0.82 0.62 0.04 1"/>  </material>
  <material name="hebi">  <color rgba="0.82 0.06 0.06 1"/>  </material>

  <!-- World can't take a visual element (at least in Gazebo). -->
  <link name="world"/>

  <link name="baseplate">
    <!-- Add a visual element -->
  </link>

  <link name="basemotor">
    <visual>
      <geometry>
        <mesh filename="package://basic134/meshes/X5.stl"
	      scale="0.001 0.001 0.001"/>
      </geometry>
      <material name="hebi"/>
    </visual>
  </link>

  <link name="lbracket">
    <!-- Add a visual element -->
  </link>

  <link name="shouldermotor">
    <visual>
      <geometry>
        <mesh filename="package://basic134/meshes/X8.stl"
	      scale="0.001 0.001 0.001"/>
      </geometry>
      <material name="hebi"/>
    </visual>
  </link>

  <link name="upperarm">
    <visual>
      <geometry>
        <mesh filename="package://basic134/meshes/basiclink.dae"/>
      </geometry>
    </visual>
  </link>

  <link name="elbowmotor">
    <visual>
      <geometry>
        <mesh filename="package://basic134/meshes/X5.stl"
	      scale="0.001 0.001 0.001"/>
      </geometry>
      <material name="hebi"/>
    </visual>
  </link>

  <link name="lowerarm">
    <visual>
      <geometry>
        <mesh filename="package://basic134/meshes/basiclink.stl"/>
      </geometry>
      <material name="wood"/>
    </visual>
  </link>

  <link name="tip"/>

</robot>
